{"uuid": "8bb177e6-a0b3-4892-9c99-7f10e98c9510", "children": ["38767145-fbcb-4387-a0fb-df75692a141f", "ff54cc8f-8de7-42e0-9ed4-85a5fd6b6e02", "251c7090-b3e9-4c55-a9e2-980341d20ddf", "a662f8a7-fe6a-41db-8ec9-40e27a628c6d", "e9d582b3-c6a1-47c6-9576-812e75753430", "4fe2e077-0b1c-4df0-bc64-0f465defe4a0", "f405e238-359e-4d4b-987a-b9841d4a7cc7", "de2ddd5c-8bae-42ba-b455-4386ecaa3cd4"], "befores": [{"name": "_Class__pytest_setup_class", "status": "passed", "start": 1606974829368, "stop": 1606974866364}], "afters": [{"name": "_Class__pytest_setup_class::0", "status": "broken", "statusDetails": {"message": "urllib3.exceptions.MaxRetryError: HTTPConnectionPool(host='127.0.0.1', port=4723): Max retries exceeded with url: /wd/hub/session/58dd9aa0-188c-42aa-afe2-62b15fcaee64 (Caused by NewConnectionError('<urllib3.connection.HTTPConnection object at 0x000001C95F0D4190>: Failed to establish a new connection: [WinError 10061] 由于目标计算机积极拒绝，无法连接。'))\n", "trace": "  File \"c:\\users\\administrator\\appdata\\local\\programs\\python\\python39\\lib\\site-packages\\allure_commons\\_allure.py\", line 185, in __call__\n    return self._fixture_function(*args, **kwargs)\n  File \"c:\\users\\administrator\\appdata\\local\\programs\\python\\python39\\lib\\site-packages\\_pytest\\fixtures.py\", line 926, in _teardown_yield_fixture\n    next(it)\n  File \"c:\\users\\administrator\\appdata\\local\\programs\\python\\python39\\lib\\site-packages\\_pytest\\python.py\", line 803, in xunit_setup_class_fixture\n    _call_with_optional_argument(func, self.obj)\n  File \"c:\\users\\administrator\\appdata\\local\\programs\\python\\python39\\lib\\site-packages\\_pytest\\python.py\", line 732, in _call_with_optional_argument\n    func(arg)\n  File \"E:\\tongzhuopy\\my_app_test\\Scripts\\test_login.py\", line 27, in teardown_class\n    self.LP_obj.driver.quit()\n  File \"c:\\users\\administrator\\appdata\\local\\programs\\python\\python39\\lib\\site-packages\\selenium\\webdriver\\remote\\webdriver.py\", line 698, in quit\n    self.execute(Command.QUIT)\n  File \"c:\\users\\administrator\\appdata\\local\\programs\\python\\python39\\lib\\site-packages\\selenium\\webdriver\\remote\\webdriver.py\", line 319, in execute\n    response = self.command_executor.execute(driver_command, params)\n  File \"c:\\users\\administrator\\appdata\\local\\programs\\python\\python39\\lib\\site-packages\\selenium\\webdriver\\remote\\remote_connection.py\", line 374, in execute\n    return self._request(command_info[0], url, body=data)\n  File \"c:\\users\\administrator\\appdata\\local\\programs\\python\\python39\\lib\\site-packages\\selenium\\webdriver\\remote\\remote_connection.py\", line 397, in _request\n    resp = self._conn.request(method, url, body=body, headers=headers)\n  File \"c:\\users\\administrator\\appdata\\local\\programs\\python\\python39\\lib\\site-packages\\urllib3\\request.py\", line 75, in request\n    return self.request_encode_url(\n  File \"c:\\users\\administrator\\appdata\\local\\programs\\python\\python39\\lib\\site-packages\\urllib3\\request.py\", line 97, in request_encode_url\n    return self.urlopen(method, url, **extra_kw)\n  File \"c:\\users\\administrator\\appdata\\local\\programs\\python\\python39\\lib\\site-packages\\urllib3\\poolmanager.py\", line 336, in urlopen\n    response = conn.urlopen(method, u.request_uri, **kw)\n  File \"c:\\users\\administrator\\appdata\\local\\programs\\python\\python39\\lib\\site-packages\\urllib3\\connectionpool.py\", line 754, in urlopen\n    return self.urlopen(\n  File \"c:\\users\\administrator\\appdata\\local\\programs\\python\\python39\\lib\\site-packages\\urllib3\\connectionpool.py\", line 754, in urlopen\n    return self.urlopen(\n  File \"c:\\users\\administrator\\appdata\\local\\programs\\python\\python39\\lib\\site-packages\\urllib3\\connectionpool.py\", line 754, in urlopen\n    return self.urlopen(\n  File \"c:\\users\\administrator\\appdata\\local\\programs\\python\\python39\\lib\\site-packages\\urllib3\\connectionpool.py\", line 726, in urlopen\n    retries = retries.increment(\n  File \"c:\\users\\administrator\\appdata\\local\\programs\\python\\python39\\lib\\site-packages\\urllib3\\util\\retry.py\", line 439, in increment\n    raise MaxRetryError(_pool, url, error or ResponseError(cause))\n"}, "start": 1606976465012, "stop": 1606976473030}], "start": 1606974829368, "stop": 1606976473030}