{"uuid": "8bb0eb2b-f567-4f44-81d6-85760d073c96", "children": ["bffdc7ec-abc9-4358-abe1-aa18d58341b4", "edb18c93-e565-4a25-b70b-d52d51f1bdd7", "48184e5e-745c-4e88-801d-19b7cacfc9c3", "aecf1e29-dec6-4df2-adcb-40f28e7b5c23", "eff65c18-de6b-4c4b-b0ad-51f57c930bd7", "83e8b172-d760-4b10-8a83-2b7bdd9c9467", "d08c286c-a053-44ba-b30b-f9bcaf75a259", "e8a24a5c-d90a-4622-96c8-abfbd7a7b05b"], "befores": [{"name": "_Class__pytest_setup_class", "status": "broken", "statusDetails": {"message": "urllib3.exceptions.MaxRetryError: HTTPConnectionPool(host='127.0.0.1', port=4723): Max retries exceeded with url: /wd/hub/session (Caused by NewConnectionError('<urllib3.connection.HTTPConnection object at 0x00000148B8EFBDF0>: Failed to establish a new connection: [WinError 10061] 由于目标计算机积极拒绝，无法连接。'))\n", "trace": "  File \"c:\\users\\administrator\\appdata\\local\\programs\\python\\python39\\lib\\site-packages\\pluggy\\callers.py\", line 187, in _multicall\n    res = hook_impl.function(*args)\n  File \"c:\\users\\administrator\\appdata\\local\\programs\\python\\python39\\lib\\site-packages\\_pytest\\fixtures.py\", line 1111, in pytest_fixture_setup\n    result = call_fixture_func(fixturefunc, request, kwargs)\n  File \"c:\\users\\administrator\\appdata\\local\\programs\\python\\python39\\lib\\site-packages\\_pytest\\fixtures.py\", line 908, in call_fixture_func\n    fixture_result = next(generator)\n  File \"c:\\users\\administrator\\appdata\\local\\programs\\python\\python39\\lib\\site-packages\\_pytest\\python.py\", line 799, in xunit_setup_class_fixture\n    _call_with_optional_argument(func, self.obj)\n  File \"c:\\users\\administrator\\appdata\\local\\programs\\python\\python39\\lib\\site-packages\\_pytest\\python.py\", line 732, in _call_with_optional_argument\n    func(arg)\n  File \"E:\\tongzhuopy\\my_app_test\\Scripts\\test_login.py\", line 21, in setup_class\n    self.LP_obj = Login_Page(get_driver())\n  File \"E:\\tongzhuopy\\my_app_test\\Base\\init_driver.py\", line 34, in get_driver\n    driver = webdriver.Remote(\"http://127.0.0.1:4723/wd/hub\", desired_caps)\n  File \"c:\\users\\administrator\\appdata\\local\\programs\\python\\python39\\lib\\site-packages\\appium\\webdriver\\webdriver.py\", line 151, in __init__\n    super().__init__(\n  File \"c:\\users\\administrator\\appdata\\local\\programs\\python\\python39\\lib\\site-packages\\selenium\\webdriver\\remote\\webdriver.py\", line 157, in __init__\n    self.start_session(capabilities, browser_profile)\n  File \"c:\\users\\administrator\\appdata\\local\\programs\\python\\python39\\lib\\site-packages\\appium\\webdriver\\webdriver.py\", line 225, in start_session\n    response = self.execute(RemoteCommand.NEW_SESSION, parameters)\n  File \"c:\\users\\administrator\\appdata\\local\\programs\\python\\python39\\lib\\site-packages\\selenium\\webdriver\\remote\\webdriver.py\", line 319, in execute\n    response = self.command_executor.execute(driver_command, params)\n  File \"c:\\users\\administrator\\appdata\\local\\programs\\python\\python39\\lib\\site-packages\\selenium\\webdriver\\remote\\remote_connection.py\", line 374, in execute\n    return self._request(command_info[0], url, body=data)\n  File \"c:\\users\\administrator\\appdata\\local\\programs\\python\\python39\\lib\\site-packages\\selenium\\webdriver\\remote\\remote_connection.py\", line 397, in _request\n    resp = self._conn.request(method, url, body=body, headers=headers)\n  File \"c:\\users\\administrator\\appdata\\local\\programs\\python\\python39\\lib\\site-packages\\urllib3\\request.py\", line 79, in request\n    return self.request_encode_body(\n  File \"c:\\users\\administrator\\appdata\\local\\programs\\python\\python39\\lib\\site-packages\\urllib3\\request.py\", line 171, in request_encode_body\n    return self.urlopen(method, url, **extra_kw)\n  File \"c:\\users\\administrator\\appdata\\local\\programs\\python\\python39\\lib\\site-packages\\urllib3\\poolmanager.py\", line 336, in urlopen\n    response = conn.urlopen(method, u.request_uri, **kw)\n  File \"c:\\users\\administrator\\appdata\\local\\programs\\python\\python39\\lib\\site-packages\\urllib3\\connectionpool.py\", line 754, in urlopen\n    return self.urlopen(\n  File \"c:\\users\\administrator\\appdata\\local\\programs\\python\\python39\\lib\\site-packages\\urllib3\\connectionpool.py\", line 754, in urlopen\n    return self.urlopen(\n  File \"c:\\users\\administrator\\appdata\\local\\programs\\python\\python39\\lib\\site-packages\\urllib3\\connectionpool.py\", line 754, in urlopen\n    return self.urlopen(\n  File \"c:\\users\\administrator\\appdata\\local\\programs\\python\\python39\\lib\\site-packages\\urllib3\\connectionpool.py\", line 726, in urlopen\n    retries = retries.increment(\n  File \"c:\\users\\administrator\\appdata\\local\\programs\\python\\python39\\lib\\site-packages\\urllib3\\util\\retry.py\", line 439, in increment\n    raise MaxRetryError(_pool, url, error or ResponseError(cause))\n"}, "start": 1606966200527, "stop": 1606966209549}], "start": 1606966200527, "stop": 1606966210474}