{"uuid": "08e4a29c-77e1-4945-af92-d95f85ab4ddd", "children": ["ddefe5e5-930b-4975-8e24-bbd1cd4817e5", "ad1d7ee5-3423-42ed-88ea-184ec4f21c67", "c03bc2ef-8410-4391-9acc-1c50c96e5f49", "3fc8fddb-2fdc-4f05-a89f-c7486a560f2f", "d9713422-8b26-42dd-afcb-8b6bdd778dbf", "c2012283-8af5-4ca5-aeee-dcfcca206dbc", "07ee6453-bd1d-4477-9845-71ebca0e3b25", "15707b63-92ed-4186-b77a-b7e671c77aa0"], "befores": [{"name": "_Class__pytest_setup_class", "status": "broken", "statusDetails": {"message": "urllib3.exceptions.MaxRetryError: HTTPConnectionPool(host='0.0.0.1', port=4723): Max retries exceeded with url: /wd/hub/session (Caused by NewConnectionError('<urllib3.connection.HTTPConnection object at 0x0000021119AFE940>: Failed to establish a new connection: [WinError 10051] 向一个无法连接的网络尝试了一个套接字操作。'))\n", "trace": "  File \"c:\\users\\administrator\\appdata\\local\\programs\\python\\python39\\lib\\site-packages\\pluggy\\callers.py\", line 187, in _multicall\n    res = hook_impl.function(*args)\n  File \"c:\\users\\administrator\\appdata\\local\\programs\\python\\python39\\lib\\site-packages\\_pytest\\fixtures.py\", line 1111, in pytest_fixture_setup\n    result = call_fixture_func(fixturefunc, request, kwargs)\n  File \"c:\\users\\administrator\\appdata\\local\\programs\\python\\python39\\lib\\site-packages\\_pytest\\fixtures.py\", line 908, in call_fixture_func\n    fixture_result = next(generator)\n  File \"c:\\users\\administrator\\appdata\\local\\programs\\python\\python39\\lib\\site-packages\\_pytest\\python.py\", line 799, in xunit_setup_class_fixture\n    _call_with_optional_argument(func, self.obj)\n  File \"c:\\users\\administrator\\appdata\\local\\programs\\python\\python39\\lib\\site-packages\\_pytest\\python.py\", line 732, in _call_with_optional_argument\n    func(arg)\n  File \"E:\\tongzhuopy\\my_app_test\\Scripts\\test_login.py\", line 21, in setup_class\n    self.LP_obj = Login_Page(get_driver())\n  File \"E:\\tongzhuopy\\my_app_test\\Base\\init_driver.py\", line 34, in get_driver\n    driver = webdriver.Remote(\"http://0.0.0.1:4723/wd/hub\", desired_caps)\n  File \"c:\\users\\administrator\\appdata\\local\\programs\\python\\python39\\lib\\site-packages\\appium\\webdriver\\webdriver.py\", line 151, in __init__\n    super().__init__(\n  File \"c:\\users\\administrator\\appdata\\local\\programs\\python\\python39\\lib\\site-packages\\selenium\\webdriver\\remote\\webdriver.py\", line 157, in __init__\n    self.start_session(capabilities, browser_profile)\n  File \"c:\\users\\administrator\\appdata\\local\\programs\\python\\python39\\lib\\site-packages\\appium\\webdriver\\webdriver.py\", line 225, in start_session\n    response = self.execute(RemoteCommand.NEW_SESSION, parameters)\n  File \"c:\\users\\administrator\\appdata\\local\\programs\\python\\python39\\lib\\site-packages\\selenium\\webdriver\\remote\\webdriver.py\", line 319, in execute\n    response = self.command_executor.execute(driver_command, params)\n  File \"c:\\users\\administrator\\appdata\\local\\programs\\python\\python39\\lib\\site-packages\\selenium\\webdriver\\remote\\remote_connection.py\", line 374, in execute\n    return self._request(command_info[0], url, body=data)\n  File \"c:\\users\\administrator\\appdata\\local\\programs\\python\\python39\\lib\\site-packages\\selenium\\webdriver\\remote\\remote_connection.py\", line 397, in _request\n    resp = self._conn.request(method, url, body=body, headers=headers)\n  File \"c:\\users\\administrator\\appdata\\local\\programs\\python\\python39\\lib\\site-packages\\urllib3\\request.py\", line 79, in request\n    return self.request_encode_body(\n  File \"c:\\users\\administrator\\appdata\\local\\programs\\python\\python39\\lib\\site-packages\\urllib3\\request.py\", line 171, in request_encode_body\n    return self.urlopen(method, url, **extra_kw)\n  File \"c:\\users\\administrator\\appdata\\local\\programs\\python\\python39\\lib\\site-packages\\urllib3\\poolmanager.py\", line 336, in urlopen\n    response = conn.urlopen(method, u.request_uri, **kw)\n  File \"c:\\users\\administrator\\appdata\\local\\programs\\python\\python39\\lib\\site-packages\\urllib3\\connectionpool.py\", line 754, in urlopen\n    return self.urlopen(\n  File \"c:\\users\\administrator\\appdata\\local\\programs\\python\\python39\\lib\\site-packages\\urllib3\\connectionpool.py\", line 754, in urlopen\n    return self.urlopen(\n  File \"c:\\users\\administrator\\appdata\\local\\programs\\python\\python39\\lib\\site-packages\\urllib3\\connectionpool.py\", line 754, in urlopen\n    return self.urlopen(\n  File \"c:\\users\\administrator\\appdata\\local\\programs\\python\\python39\\lib\\site-packages\\urllib3\\connectionpool.py\", line 726, in urlopen\n    retries = retries.increment(\n  File \"c:\\users\\administrator\\appdata\\local\\programs\\python\\python39\\lib\\site-packages\\urllib3\\util\\retry.py\", line 439, in increment\n    raise MaxRetryError(_pool, url, error or ResponseError(cause))\n"}, "start": 1606974365269, "stop": 1606974365273}], "start": 1606974365269, "stop": 1606974366183}